Workbook

Sheet Summary Dashboard
A1: PhonePe Transaction Summary Dashboard
A3: Total Transactions | B3: =COUNTA('All Transactions'!E:E)-1 -> 1930
A4: Total Debits (Spends) | B4: =SUMIF('All Transactions'!G:G,"DEBIT",'All Transactions'!H:H) -> 979706.5
A5: Total Credits (Income) | B5: =SUMIF('All Transactions'!G:G,"CREDIT",'All Transactions'!H:H) -> 645469.9
A6: Net Cash Flow | B6: =B5-B4 -> -334236.6
A9: Top 10 Highest Debit Transactions
A10: Date | B10: Details | C10: Amount (INR)
A11: Jun 07, 2025 | B11: Transfer to XXXX7370 | C11: 31400
A12: Feb 08, 2026 | B12: Paid to Abhi 💗 | C12: 30000
A13: Jun 07, 2025 | B13: Transfer to XXXXXX6646 | C13: 27900
A14: Jul 30, 2025 | B14: Paid to Kotak Mahindra Bank Ltd | C14: 25000
A15: Jul 15, 2025 | B15: Transfer to XXXX7370 | C15: 25000
A16: Jun 25, 2025 | B16: Paid to QSPIDERSUTEST YANTRA SW SOLIP LTD AIR1QlQW0jHkKpWos6T5769134280QPAY02 | C16: 21000
A17: Aug 25, 2025 | B17: Transfer to XXXXXXXX1137 | C17: 20000
A18: Aug 25, 2025 | B18: Transfer to XXXX7370 | C18: 20000
A19: Aug 25, 2025 | B19: Transfer to XXXXXXXX1137 | C19: 18000
A20: Aug 25, 2025 | B20: Transfer to XXXXXX6646 | C20: 18000

Sheet All Transactions
A1: day | B1: month2 | C1: month | D1: year | E1: Date | F1: Time | G1: Type | H1: Amount (INR) | I1: Details | J1: Transaction ID | K1: UTR No. | L1: Account Info | M1: days | N1: date2
A2: =MID(E2,5,2) -> 04 | B2: =_xlfn.SWITCH(Table4[[#This Row],[month]],"jan",1,"feb",2,"mar",3,"apr",4,"may",5,"jun",6,"jul",7,"aug",8,"sep",9,"oct",10,"nov",11,"dec",12,"no month") -> 6 | C2: =LEFT('All Transactions'!$E2,3) -> Jun | D2: =RIGHT(E2,4) -> 2026 | E2: Jun 04, 2026 | F2: 10:11 am | G2: DEBIT | H2: 27 | I2: Paid to Kodithyala Tejasvi | J2: T2606041011314875701288 | K2: 045220263536 | L2: Paid by XXXXXXXX1137 | M2: =TEXT(A2,"dddd") -> Wednesday | N2: =DATE(Table4[[#This Row],[year]],Table4[[#This Row],[month2]],Table4[[#This Row],[day]]) -> 46177
A3: =MID(E3,5,2) -> 04 | B3: =_xlfn.SWITCH(Table4[[#This Row],[month]],"jan",1,"feb",2,"mar",3,"apr",4,"may",5,"jun",6,"jul",7,"aug",8,"sep",9,"oct",10,"nov",11,"dec",12,"no month") -> 6 | C3: =LEFT('All Transactions'!$E3,3) -> Jun | D3: =RIGHT(E3,4) -> 2026 | E3: Jun 04, 2026 | F3: 10:10 am | G3: DEBIT | H3: 10 | I3: Paid to Kodithyala Tejasvi | J3: T2606041010294837143118 | K3: 464727463411 | L3: Paid by XXXXXXXX1137 | M3: =TEXT(A3,"dddd") -> Wednesday | N3: =DATE(Table4[[#This Row],[year]],Table4[[#This Row],[month2]],Table4[[#This Row],[day]]) -> 46177
A4: =MID(E4,5,2) -> 04 | B4: =_xlfn.SWITCH(Table4[[#This Row],[month]],"jan",1,"feb",2,"mar",3,"apr",4,"may",5,"jun",6,"jul",7,"aug",8,"sep",9,"oct",10,"nov",11,"dec",12,"no month") -> 6 | C4: =LEFT('All Transactions'!$E4,3) -> Jun | D4: =RIGHT(E4,4) -> 2026 | E4: Jun 04, 2026 | F4: 10:08 am | G4: DEBIT | H4: 70 | I4: Paid to GANGARABOINA MADHUKA | J4: T2606041008374360542582 | K4: 062979462011 | L4: Paid by XXXXXXXX1137 | M4: =TEXT(A4,"dddd") -> Wednesday | N4: =DATE(Table4[[#This Row],[year]],Table4[[#This Row],[month2]],Table4[[#This Row],[day]]) -> 46177
A5: =MID(E5,5,2) -> 04 | B5: =_xlfn.SWITCH(Table4[[#This Row],[month]],"jan",1,"feb",2,"mar",3,"apr",4,"may",5,"jun",6,"jul",7,"aug",8,"sep",9,"oct",10,"nov",11,"dec",12,"no month") -> 6 | C5: =LEFT('All Transactions'!$E5,3) -> Jun | D5: =RIGHT(E5,4) -> 2026 | E5: Jun 04, 2026 | F5: 09:09 am | G5: DEBIT | H5: 20 | I5: Paid to JUNNU TEA POINT | J5: T2606040909435947046539 | K5: 141109617820 | L5: Paid by XXXXXXXX1137 | M5: =TEXT(A5,"dddd") -> Wednesday | N5: =DATE(Table4[[#This Row],[year]],Table4[[#This Row],[month2]],Table4[[#This Row],[day]]) -> 46177
A6: =MID(E6,5,2) -> 04 | B6: =_xlfn.SWITCH(Table4[[#This Row],[month]],"jan",1,"feb",2,"mar",3,"apr",4,"may",5,"jun",6,"jul",7,"aug",8,"sep",9,"oct",10,"nov",11,"dec",12,"no month") -> 6 | C6: =LEFT('All Transactions'!$E6,3) -> Jun | D6: =RIGHT(E6,4) -> 2026 | E6: Jun 04, 2026 | F6: 08:29 am | G6: DEBIT | H6: 673 | I6: Transfer to XXXXXXXX1137 | J6: T2606040829273598415025 | K6: 684310994967 | L6: Paid by XXXX7370 | M6: =TEXT(A6,"dddd") -> Wednesday | N6: =DATE(Table4[[#This Row],[year]],Table4[[#This Row],[month2]],Table4[[#This Row],[day]]) -> 46177
A7: =MID(E7,5,2) -> 04 | B7: =_xlfn.SWITCH(Table4[[#This Row],[month]],"jan",1,"feb",2,"mar",3,"apr",4,"may",5,"jun",6,"jul",7,"aug",8,"sep",9,"oct",10,"nov",11,"dec",12,"no month") -> 6 | C7: =LEFT('All Transactions'!$E7,3) -> Jun | D7: =RIGHT(E7,4) -> 2026 | E7: Jun 04, 2026 | F7: 06:00 am | G7: DEBIT | H7: 673 | I7: Payment to RentomojoPvtLtd | J7: OLEX2606040600103873282437 | K7: 615506335127 | L7: Paid by XXXXXXXX1137 | M7: =TEXT(A7,"dddd") -> Wednesday | N7: =DATE(Table4[[#This Row],[year]],Table4[[#This Row],[month2]],Table4[[#This Row],[day]]) -> 46177
A8: =MID(E8,5,2) -> 03 | B8: =_xlfn.SWITCH(Table4[[#This Row],[month]],"jan",1,"feb",2,"mar",3,"apr",4,"may",5,"jun",6,"jul",7,"aug",8,"sep",9,"oct",10,"nov",11,"dec",12,"no month") -> 6 | C8: =LEFT('All Transactions'!$E8,3) -> Jun | D8: =RIGHT(E8,4) -> 2026 | E8: Jun 03, 2026 | F8: 09:07 pm | G8: CREDIT | H8: 17 | I8: Received from phani | J8: T2606032107243476749558 | K8: 336002225185 | L8: Credited to XXXXXXXX1137 | M8: =TEXT(A8,"dddd") -> Tuesday | N8: =DATE(Table4[[#This Row],[year]],Table4[[#This Row],[month2]],Table4[[#This Row],[day]]) -> 46176
A9: =MID(E9,5,2) -> 03 | B9: =_xlfn.SWITCH(Table4[[#This Row],[month]],"jan",1,"feb",2,"mar",3,"apr",4,"may",5,"jun",6,"jul",7,"aug",8,"sep",9,"oct",10,"nov",11,"dec",12,"no month") -> 6 | C9: =LEFT('All Transactions'!$E9,3) -> Jun | D9: =RIGHT(E9,4) -> 2026 | E9: Jun 03, 2026 | F9: 08:47 pm | G9: CREDIT | H9: 76 | I9: Received from BACHU SHIVA SHANKAR | J9: T2606032047526816822372 | K9: 652044153724 | L9: Credited to XXXXXXXX1137 | M9: =TEXT(A9,"dddd") -> Tuesday | N9: =DATE(Table4[[#This Row],[year]],Table4[[#This Row],[month2]],Table4[[#This Row],[day]]) -> 46176
A10: =MID(E10,5,2) -> 03 | B10: =_xlfn.SWITCH(Table4[[#This Row],[month]],"jan",1,"feb",2,"mar",3,"apr",4,"may",5,"jun",6,"jul",7,"aug",8,"sep",9,"oct",10,"nov",11,"dec",12,"no month") -> 6 | C10: =LEFT('All Transactions'!$E10,3) -> Jun | D10: =RIGHT(E10,4) -> 2026 | E10: Jun 03, 2026 | F10: 06:25 pm | G10: DEBIT | H10: 40 | I10: Paid to GANGARABOINA MADHUKA | J10: T2606031825293685051886 | K10: 789171415403 | L10: Paid by XXXXXXXX1137 | M10: =TEXT(A10,"dddd") -> Tuesday | N10: =DATE(Table4[[#This Row],[year]],Table4[[#This Row],[month2]],Table4[[#This Row],[day]]) -> 46176
A11: =MID(E11,5,2) -> 03 | B11: =_xlfn.SWITCH(Table4[[#This Row],[month]],"jan",1,"feb",2,"mar",3,"apr",4,"may",5,"jun",6,"jul",7,"aug",8,"sep",9,"oct",10,"nov",11,"dec",12,"no month") -> 6 | C11: =LEFT('All Transactions'!$E11,3) -> Jun | D11: =RIGHT(E11,4) -> 2026 | E11: Jun 03, 2026 | F11: 02:51 pm | G11: DEBIT | H11: 10 | I11: Paid to Kodithyala Tejasvi | J11: T2606031451095158039712 | K11: 673509106980 | L11: Paid by XXXXXXXX1137 | M11: =TEXT(A11,"dddd") -> Tuesday | N11: =DATE(Table4[[#This Row],[year]],Table4[[#This Row],[month2]],Table4[[#This Row],[day]]) -> 46176
A12: =MID(E12,5,2) -> 03 | B12: =_xlfn.SWITCH(Table4[[#This Row],[month]],"jan",1,"feb",2,"mar",3,"apr",4,"may",5,"jun",6,"jul",7,"aug",8,"sep",9,"oct",10,"nov",11,"dec",12,"no month") -> 6 | C12: =LEFT('All Transactions'!$E12,3) -> Jun | D12: =RIGHT(E12,4) -> 2026 | E12: Jun 03, 2026 | F12: 02:48 pm | G12: DEBIT | H12: 75 | I12: Paid to B22_YOUSUFGUDA_2 | J12: T2606031448258520977879 | K12: 227595184341 | L12: Paid by XXXX7370 | M12: =TEXT(A12,"dddd") -> Tuesday | N12: =DATE(Table4[[#This Row],[year]],Table4[[#This Row],[month2]],Table4[[#This Row],[day]]) -> 46176
A13: =MID(E13,5,2) -> 03 | B13: =_xlfn.SWITCH(Table4[[#This Row],[month]],"jan",1,"feb",2,"mar",3,"apr",4,"may",5,"jun",6,"jul",7,"aug",8,"sep",9,"oct",10,"nov",11,"dec",12,"no month") -> 6 | C13: =LEFT('All Transactions'!$E13,3) -> Jun | D13: =RIGHT(E13,4) -> 2026 | E13: Jun 03, 2026 | F13: 02:33 pm | G13: DEBIT | H13: 5 | I13: Paid to Kodithyala Tejasvi | J13: T2606031433292725176840 | K13: 378486486222 | L13: Paid by XXXXXXXX1137 | M13: =TEXT(A13,"dddd") -> Tuesday | N13: =DATE(Table4[[#This Row],[year]],Table4[[#This Row],[month2]],Table4[[#This Row],[day]]) -> 46176
... A747: =MID(E747,5,2) -> 12 | B747: =_xlfn.SWITCH(Table4[[#This Row],[month]],"jan",1,"feb",2,"mar",3,"apr",4,"may",5,"jun",6,"jul",7,"aug",8,"sep",9,"oct",10,"nov",11,"dec",12,"no month") -> 3 | C747: =LEFT('All Transactions'!$E747,3) -> Mar | D747: =RIGHT(E747,4) -> 2026 | E747: Mar 12, 2026 | F747: 11:16 am | G747: CREDIT | H747: 60 | I747: Received from Manikanta | J747: T2603121116444633084840 | K747: 962112293900 | L747: Credited to XXXXXXXX1137 | M747: =TEXT(A747,"dddd") -> Thursday | N747: =DATE(Table4[[#This Row],[year]],Table4[[#This Row],[month2]],Table4[[#This Row],[day]]) -> 46093
A748: =MID(E748,5,2) -> 12 | B748: =_xlfn.SWITCH(Table4[[#This Row],[month]],"jan",1,"feb",2,"mar",3,"apr",4,"may",5,"jun",6,"jul",7,"aug",8,"sep",9,"oct",10,"nov",11,"dec",12,"no month") -> 3 | C748: =LEFT('All Transactions'!$E748,3) -> Mar | D748: =RIGHT(E748,4) -> 2026 | E748: Mar 12, 2026 | F748: 10:18 am | G748: DEBIT | H748: 3661.8 | I748: Paid to Narsimha Reddy Engineering College PTM60312802827912628241202603121018 | K748: 201755603751 | L748: Paid by XXXXXXXX1137 | M748: =TEXT(A748,"dddd") -> Thursday | N748: =DATE(Table4[[#This Row],[year]],Table4[[#This Row],[month2]],Table4[[#This Row],[day]]) -> 46093
A749: =MID(E749,5,2) -> 12 | B749: =_xlfn.SWITCH(Table4[[#This Row],[month]],"jan",1,"feb",2,"mar",3,"apr",4,"may",5,"jun",6,"jul",7,"aug",8,"sep",9,"oct",10,"nov",11,"dec",12,"no month") -> 3 | C749: =LEFT('All Transactions'!$E749,3) -> Mar | D749: =RIGHT(E749,4) -> 2026 | E749: Mar 12, 2026 | F749: 10:12 am | G749: CREDIT | H749: 4000 | I749: Received from Babai | J749: T2603121012418335324743 | K749: 528910406974 | L749: Credited to XXXXXXXX1137 | M749: =TEXT(A749,"dddd") -> Thursday | N749: =DATE(Table4[[#This Row],[year]],Table4[[#This Row],[month2]],Table4[[#This Row],[day]]) -> 46093
A750: =MID(E750,5,2) -> 11 | B750: =_xlfn.SWITCH(Table4[[#This Row],[month]],"jan",1,"feb",2,"mar",3,"apr",4,"may",5,"jun",6,"jul",7,"aug",8,"sep",9,"oct",10,"nov",11,"dec",12,"no month") -> 3 | C750: =LEFT('All Transactions'!$E750,3) -> Mar | D750: =RIGHT(E750,4) -> 2026 | E750: Mar 11, 2026 | F750: 09:11 pm | G750: DEBIT | H750: 10 | I750: Paid to Shivaparvathi kirana general merchant | J750: T2603112111282360388611 | K750: 707452042790 | L750: Paid by XXXXXXXX1137 | M750: =TEXT(A750,"dddd") -> Wednesday | N750: =DATE(Table4[[#This Row],[year]],Table4[[#This Row],[month2]],Table4[[#This Row],[day]]) -> 46092
A751: =MID(E751,5,2) -> 11 | B751: =_xlfn.SWITCH(Table4[[#This Row],[month]],"jan",1,"feb",2,"mar",3,"apr",4,"may",5,"jun",6,"jul",7,"aug",8,"sep",9,"oct",10,"nov",11,"dec",12,"no month") -> 3 | C751: =LEFT('All Transactions'!$E751,3) -> Mar | D751: =RIGHT(E751,4) -> 2026 | E751: Mar 11, 2026 | F751: 09:10 pm | G751: DEBIT | H751: 30 | I751: Paid to Shaheen Chicken Maarket | J751: T2603112110316806416658 | K751: 294846718737 | L751: Paid by XXXXXXXX1137 | M751: =TEXT(A751,"dddd") -> Wednesday | N751: =DATE(Table4[[#This Row],[year]],Table4[[#This Row],[month2]],Table4[[#This Row],[day]]) -> 46092
A752: =MID(E752,5,2) -> 11 | B752: =_xlfn.SWITCH(Table4[[#This Row],[month]],"jan",1,"feb",2,"mar",3,"apr",4,"may",5,"jun",6,"jul",7,"aug",8,"sep",9,"oct",10,"nov",11,"dec",12,"no month") -> 3 | C752: =LEFT('All Transactions'!$E752,3) -> Mar | D752: =RIGHT(E752,4) -> 2026 | E752: Mar 11, 2026 | F752: 11:16 am | G752: DEBIT | H752: 60 | I752: Paid to Manikanta | J752: T2603111116011860852908 | K752: 964483539313 | L752: Paid by XXXXXXXX1137 | M752: =TEXT(A752,"dddd") -> Wednesday | N752: =DATE(Table4[[#This Row],[year]],Table4[[#This Row],[month2]],Table4[[#This Row],[day]]) -> 46092
A753: =MID(E753,5,2) -> 10 | B753: =_xlfn.SWITCH(Table4[[#This Row],[month]],"jan",1,"feb",2,"mar",3,"apr",4,"may",5,"jun",6,"jul",7,"aug",8,"sep",9,"oct",10,"nov",11,"dec",12,"no month") -> 3 | C753: =LEFT('All Transactions'!$E753,3) -> Mar | D753: =RIGHT(E753,4) -> 2026 | E753: Mar 10, 2026 | F753: 10:12 am | G753: DEBIT | H753: 40 | I753: Paid to Mahalakshmi Vegetables | J753: T2603101012092977634860 | K753: 187390887701 | L753: Paid by XXXXXXXX1137 | M753: =TEXT(A753,"dddd") -> Tuesday | N753: =DATE(Table4[[#This Row],[year]],Table4[[#This Row],[month2]],Table4[[#This Row],[day]]) -> 46091
A754: =MID(E754,5,2) -> 09 | B754: =_xlfn.SWITCH(Table4[[#This Row],[month]],"jan",1,"feb",2,"mar",3,"apr",4,"may",5,"jun",6,"jul",7,"aug",8,"sep",9,"oct",10,"nov",11,"dec",12,"no month") -> 3 | C754: =LEFT('All Transactions'!$E754,3) -> Mar | D754: =RIGHT(E754,4) -> 2026 | E754: Mar 09, 2026 | F754: 11:24 pm | G754: DEBIT | H754: 40 | I754: Paid to Charan 💗 | J754: T2603092324265952066037 | K754: 920583072131 | L754: Paid by XXXXXXXX1137 | M754: =TEXT(A754,"dddd") -> Monday | N754: =DATE(Table4[[#This Row],[year]],Table4[[#This Row],[month2]],Table4[[#This Row],[day]]) -> 46090
A755: =MID(E755,5,2) -> 09 | B755: =_xlfn.SWITCH(Table4[[#This Row],[month]],"jan",1,"feb",2,"mar",3,"apr",4,"may",5,"jun",6,"jul",7,"aug",8,"sep",9,"oct",10,"nov",11,"dec",12,"no month") -> 3 | C755: =LEFT('All Transactions'!$E755,3) -> Mar | D755: =RIGHT(E755,4) -> 2026 | E755: Mar 09, 2026 | F755: 11:23 pm | G755: DEBIT | H755: 147 | I755: Paid to SWIGGY | J755: T2603092323316432677117 | K755: 747326013752 | L755: Paid by XXXXXXXX1137 | M755: =TEXT(A755,"dddd") -> Monday | N755: =DATE(Table4[[#This Row],[year]],Table4[[#This Row],[month2]],Table4[[#This Row],[day]]) -> 46090
A756: =MID(E756,5,2) -> 09 | B756: =_xlfn.SWITCH(Table4[[#This Row],[month]],"jan",1,"feb",2,"mar",3,"apr",4,"may",5,"jun",6,"jul",7,"aug",8,"sep",9,"oct",10,"nov",11,"dec",12,"no month") -> 3 | C756: =LEFT('All Transactions'!$E756,3) -> Mar | D756: =RIGHT(E756,4) -> 2026 | E756: Mar 09, 2026 | F756: 07:36 pm | G756: CREDIT | H756: 250 | I756: Received from Charan 💗 | J756: T2603091936573672532277 | K756: 116822460073 | L756: Credited to XXXXXXXX1137 | M756: =TEXT(A756,"dddd") -> Monday | N756: =DATE(Table4[[#This Row],[year]],Table4[[#This Row],[month2]],Table4[[#This Row],[day]]) -> 46090
A757: =MID(E757,5,2) -> 09 | B757: =_xlfn.SWITCH(Table4[[#This Row],[month]],"jan",1,"feb",2,"mar",3,"apr",4,"may",5,"jun",6,"jul",7,"aug",8,"sep",9,"oct",10,"nov",11,"dec",12,"no month") -> 3 | C757: =LEFT('All Transactions'!$E757,3) -> Mar | D757: =RIGHT(E757,4) -> 2026 | E757: Mar 09, 2026 | F757: 06:42 pm | G757: DEBIT | H757: 300 | I757: Paid to RAJAMMA VEMULA | J757: T2603091842370219580366 | K757: 449355061023 | L757: Paid by XXXXXXXX1137 | M757: =TEXT(A757,"dddd") -> Monday | N757: =DATE(Table4[[#This Row],[year]],Table4[[#This Row],[month2]],Table4[[#This Row],[day]]) -> 46090
A758: =MID(E758,5,2) -> 09 | B758: =_xlfn.SWITCH(Table4[[#This Row],[month]],"jan",1,"feb",2,"mar",3,"apr",4,"may",5,"jun",6,"jul",7,"aug",8,"sep",9,"oct",10,"nov",11,"dec",12,"no month") -> 3 | C758: =LEFT('All Transactions'!$E758,3) -> Mar | D758: =RIGHT(E758,4) -> 2026 | E758: Mar 09, 2026 | F758: 06:41 pm | G758: CREDIT | H758: 800 | I758: Received from Manikanta | J758: T2603091841428477592855 | K758: 079020923038 | L758: Credited to XXXXXXXX1137 | M758: =TEXT(A758,"dddd") -> Monday | N758: =DATE(Table4[[#This Row],[year]],Table4[[#This Row],[month2]],Table4[[#This Row],[day]]) -> 46090
A759: =MID(E759,5,2) -> 09 | B759: =_xlfn.SWITCH(Table4[[#This Row],[month]],"jan",1,"feb",2,"mar",3,"apr",4,"may",5,"jun",6,"jul",7,"aug",8,"sep",9,"oct",10,"nov",11,"dec",12,"no month") -> 3 | C759: =LEFT('All Transactions'!$E759,3) -> Mar | D759: =RIGHT(E759,4) -> 2026 | E759: Mar 09, 2026 | F759: 10:02 am | G759: DEBIT | H759: 70 | I759: Paid to Sri Durga bhavani reddy tiffin centre | J759: T2603091002384717451639 | K759: 129561376004 | L759: Paid by XXXXXXXX1137 | M759: =TEXT(A759,"dddd") -> Monday | N759: =DATE(Table4[[#This Row],[year]],Table4[[#This Row],[month2]],Table4[[#This Row],[day]]) -> 46090
A760: =MID(E760,5,2) -> 08 | B760: =_xlfn.SWITCH(Table4[[#This Row],[month]],"jan",1,"feb",2,"mar",3,"apr",4,"may",5,"jun",6,"jul",7,"aug",8,"sep",9,"oct",10,"nov",11,"dec",12,"no month") -> 3 | C760: =LEFT('All Transactions'!$E760,3) -> Mar | D760: =RIGHT(E760,4) -> 2026 | E760: Mar 08, 2026 | F760: 11:10 pm | G760: DEBIT | H760: 100 | I760: Paid to Jatprole Filling Station | J760: T2603082310233826218924 | K760: 903788678537 | L760: Paid by XXXXXXXX1137 | M760: =TEXT(A760,"dddd") -> Sunday | N760: =DATE(Table4[[#This Row],[year]],Table4[[#This Row],[month2]],Table4[[#This Row],[day]]) -> 46089
... A856: =MID(E856,5,2) -> 24 | B856: =_xlfn.SWITCH(Table4[[#This Row],[month]],"jan",1,"feb",2,"mar",3,"apr",4,"may",5,"jun",6,"jul",7,"aug",8,"sep",9,"oct",10,"nov",11,"dec",12,"no month") -> 2 | C856: =LEFT('All Transactions'!$E856,3) -> Feb | D856: =RIGHT(E856,4) -> 2026 | E856: Feb 24, 2026 | F856: 06:19 pm | G856: DEBIT | H856: 10 | I856: Paid to Sri Sai super cool drink 2 ₹ 1 Gift Card ₹ 9 | J856: T2602241819381978058161 | K856: 486325389493 | L856: Paid by XXXXXXXX1137 | M856: =TEXT(A856,"dddd") -> Tuesday | N856: =DATE(Table4[[#This Row],[year]],Table4[[#This Row],[month2]],Table4[[#This Row],[day]]) -> 46077
A857: =MID(E857,5,2) -> 24 | B857: =_xlfn.SWITCH(Table4[[#This Row],[month]],"jan",1,"feb",2,"mar",3,"apr",4,"may",5,"jun",6,"jul",7,"aug",8,"sep",9,"oct",10,"nov",11,"dec",12,"no month") -> 2 | C857: =LEFT('All Transactions'!$E857,3) -> Feb | D857: =RIGHT(E857,4) -> 2026 | E857: Feb 24, 2026 | F857: 12:08 pm | G857: CREDIT | H857: 1 | I857: Cashback from PhonePe Gift Card | J857: T2602241208084032157414 | L857: Credited to | M857: =TEXT(A857,"dddd") -> Tuesday | N857: =DATE(Table4[[#This Row],[year]],Table4[[#This Row],[month2]],Table4[[#This Row],[day]]) -> 46077
A858: =MID(E858,5,2) -> 24 | B858: =_xlfn.SWITCH(Table4[[#This Row],[month]],"jan",1,"feb",2,"mar",3,"apr",4,"may",5,"jun",6,"jul",7,"aug",8,"sep",9,"oct",10,"nov",11,"dec",12,"no month") -> 2 | C858: =LEFT('All Transactions'!$E858,3) -> Feb | D858: =RIGHT(E858,4) -> 2026 | E858: Feb 24, 2026 | F858: 12:07 pm | G858: CREDIT | H858: 2.5 | I858: Cashback from PhonePe Gift Card | J858: T2602241207533286139354 | L858: Credited to | M858: =TEXT(A858,"dddd") -> Tuesday | N858: =DATE(Table4[[#This Row],[year]],Table4[[#This Row],[month2]],Table4[[#This Row],[day]]) -> 46077
A859: =MID(E859,5,2) -> 24 | B859: =_xlfn.SWITCH(Table4[[#This Row],[month]],"jan",1,"feb",2,"mar",3,"apr",4,"may",5,"jun",6,"jul",7,"aug",8,"sep",9,"oct",10,"nov",11,"dec",12,"no month") -> 2 | C859: =LEFT('All Transactions'!$E859,3) -> Feb | D859: =RIGHT(E859,4) -> 2026 | E859: Feb 24, 2026 | F859: 12:07 pm | G859: CREDIT | H859: 1 | I859: Cashback from PhonePe Gift Card | J859: T2602241207459160484970 | L859: Credited to | M859: =TEXT(A859,"dddd") -> Tuesday | N859: =DATE(Table4[[#This Row],[year]],Table4[[#This Row],[month2]],Table4[[#This Row],[day]]) -> 46077
A860: =MID(E860,5,2) -> 24 | B860: =_xlfn.SWITCH(Table4[[#This Row],[month]],"jan",1,"feb",2,"mar",3,"apr",4,"may",5,"jun",6,"jul",7,"aug",8,"sep",9,"oct",10,"nov",11,"dec",12,"no month") -> 2 | C860: =LEFT('All Transactions'!$E860,3) -> Feb | D860: =RIGHT(E860,4) -> 2026 | E860: Feb 24, 2026 | F860: 11:45 am | G860: DEBIT | H860: 40 | I860: Paid to GOVINDAARAPU RAJU | J860: T2602241145268772709714 | K860: 839253122102 | L860: Paid by XXXXXXXX1137 | M860: =TEXT(A860,"dddd") -> Tuesday | N860: =DATE(Table4[[#This Row],[year]],Table4[[#This Row],[month2]],Table4[[#This Row],[day]]) -> 46077
A861: =MID(E861,5,2) -> 24 | B861: =_xlfn.SWITCH(Table4[[#This Row],[month]],"jan",1,"feb",2,"mar",3,"apr",4,"may",5,"jun",6,"jul",7,"aug",8,"sep",9,"oct",10,"nov",11,"dec",12,"no month") -> 2 | C861: =LEFT('All Transactions'!$E861,3) -> Feb | D861: =RIGHT(E861,4) -> 2026 | E861: Feb 24, 2026 | F861: 12:01 am | G861: DEBIT | H861: 20 | I861: Paid to LAIBAS CAFE | J861: T2602240001009736939055 | K861: 188577753829 | L861: Paid by XXXXXXXX1137 | M861: =TEXT(A861,"dddd") -> Tuesday | N861: =DATE(Table4[[#This Row],[year]],Table4[[#This Row],[month2]],Table4[[#This Row],[day]]) -> 46077
A862: =MID(E862,5,2) -> 23 | B862: =_xlfn.SWITCH(Table4[[#This Row],[month]],"jan",1,"feb",2,"mar",3,"apr",4,"may",5,"jun",6,"jul",7,"aug",8,"sep",9,"oct",10,"nov",11,"dec",12,"no month") -> 2 | C862: =LEFT('All Transactions'!$E862,3) -> Feb | D862: =RIGHT(E862,4) -> 2026 | E862: Feb 23, 2026 | F862: 11:29 pm | G862: DEBIT | H862: 102.44 | I862: Paid to ZOMATO LIMITED | J862: T2602232329469327009466 | K862: 326608300898 | L862: Paid by XXXXXXXX1137 | M862: =TEXT(A862,"dddd") -> Monday | N862: =DATE(Table4[[#This Row],[year]],Table4[[#This Row],[month2]],Table4[[#This Row],[day]]) -> 46076
A863: =MID(E863,5,2) -> 23 | B863: =_xlfn.SWITCH(Table4[[#This Row],[month]],"jan",1,"feb",2,"mar",3,"apr",4,"may",5,"jun",6,"jul",7,"aug",8,"sep",9,"oct",10,"nov",11,"dec",12,"no month") -> 2 | C863: =LEFT('All Transactions'!$E863,3) -> Feb | D863: =RIGHT(E863,4) -> 2026 | E863: Feb 23, 2026 | F863: 11:29 pm | G863: CREDIT | H863: 100 | I863: Received from Charan 💗 | J863: T2602232329299318865390 | K863: 240116073032 | L863: Credited to XXXXXXXX1137 | M863: =TEXT(A863,"dddd") -> Monday | N863: =DATE(Table4[[#This Row],[year]],Table4[[#This Row],[month2]],Table4[[#This Row],[day]]) -> 46076
A864: =MID(E864,5,2) -> 23 | B864: =_xlfn.SWITCH(Table4[[#This Row],[month]],"jan",1,"feb",2,"mar",3,"apr",4,"may",5,"jun",6,"jul",7,"aug",8,"sep",9,"oct",10,"nov",11,"dec",12,"no month") -> 2 | C864: =LEFT('All Transactions'!$E864,3) -> Feb | D864: =RIGHT(E864,4) -> 2026 | E864: Feb 23, 2026 | F864: 08:20 pm | G864: DEBIT | H864: 470 | I864: Paid to KULDEEP CHHETRI | J864: T2602232020408236557082 | K864: 788944154797 | L864: Paid by XXXXXXXX1137 | M864: =TEXT(A864,"dddd") -> Monday | N864: =DATE(Table4[[#This Row],[year]],Table4[[#This Row],[month2]],Table4[[#This Row],[day]]) -> 46076
A865: =MID(E865,5,2) -> 23 | B865: =_xlfn.SWITCH(Table4[[#This Row],[month]],"jan",1,"feb",2,"mar",3,"apr",4,"may",5,"jun",6,"jul",7,"aug",8,"sep",9,"oct",10,"nov",11,"dec",12,"no month") -> 2 | C865: =LEFT('All Transactions'!$E865,3) -> Feb | D865: =RIGHT(E865,4) -> 2026 | E865: Feb 23, 2026 | F865: 08:20 pm | G865: CREDIT | H865: 200 | I865: Received from Charan 💗 | J865: T2602232020262586057040 | K865: 772024139307 | L865: Credited to XXXXXXXX1137 | M865: =TEXT(A865,"dddd") -> Monday | N865: =DATE(Table4[[#This Row],[year]],Table4[[#This Row],[month2]],Table4[[#This Row],[day]]) -> 46076
A866: =MID(E866,5,2) -> 23 | B866: =_xlfn.SWITCH(Table4[[#This Row],[month]],"jan",1,"feb",2,"mar",3,"apr",4,"may",5,"jun",6,"jul",7,"aug",8,"sep",9,"oct",10,"nov",11,"dec",12,"no month") -> 2 | C866: =LEFT('All Transactions'!$E866,3) -> Feb | D866: =RIGHT(E866,4) -> 2026 | E866: Feb 23, 2026 | F866: 08:17 pm | G866: CREDIT | H866: 200 | I866: Received from Manikanta | J866: T2602232017391167746726 | K866: 899351920465 | L866: Credited to XXXXXXXX1137 | M866: =TEXT(A866,"dddd") -> Monday | N866: =DATE(Table4[[#This Row],[year]],Table4[[#This Row],[month2]],Table4[[#This Row],[day]]) -> 46076
A867: =MID(E867,5,2) -> 23 | B867: =_xlfn.SWITCH(Table4[[#This Row],[month]],"jan",1,"feb",2,"mar",3,"apr",4,"may",5,"jun",6,"jul",7,"aug",8,"sep",9,"oct",10,"nov",11,"dec",12,"no month") -> 2 | C867: =LEFT('All Transactions'!$E867,3) -> Feb | D867: =RIGHT(E867,4) -> 2026 | E867: Feb 23, 2026 | F867: 07:29 pm | G867: DEBIT | H867: 120 | I867: Paid to Charan 💗 | J867: T2602231929382187452670 | K867: 981023739573 | L867: Paid by XXXXXXXX1137 | M867: =TEXT(A867,"dddd") -> Monday | N867: =DATE(Table4[[#This Row],[year]],Table4[[#This Row],[month2]],Table4[[#This Row],[day]]) -> 46076
A868: =MID(E868,5,2) -> 23 | B868: =_xlfn.SWITCH(Table4[[#This Row],[month]],"jan",1,"feb",2,"mar",3,"apr",4,"may",5,"jun",6,"jul",7,"aug",8,"sep",9,"oct",10,"nov",11,"dec",12,"no month") -> 2 | C868: =LEFT('All Transactions'!$E868,3) -> Feb | D868: =RIGHT(E868,4) -> 2026 | E868: Feb 23, 2026 | F868: 11:49 am | G868: DEBIT | H868: 20 | I868: Paid to SAI YOGESHWARA KIRANAM AND GENERAL STORE Gift Card | J868: T2602231149357725168833 | L868: Paid by | M868: =TEXT(A868,"dddd") -> Monday | N868: =DATE(Table4[[#This Row],[year]],Table4[[#This Row],[month2]],Table4[[#This Row],[day]]) -> 46076
...
